Traceback (most recent call last):
  File "C:\Users\rullu\AppData\Local\Programs\Python\Python310\lib\site-packages\jupyter_cache\executors\utils.py", line 58, in single_nb_execution
    executenb(
  File "C:\Users\rullu\AppData\Local\Programs\Python\Python310\lib\site-packages\nbclient\client.py", line 1319, in execute
    return NotebookClient(nb=nb, resources=resources, km=km, **kwargs).execute()
  File "C:\Users\rullu\AppData\Local\Programs\Python\Python310\lib\site-packages\jupyter_core\utils\__init__.py", line 165, in wrapped
    return loop.run_until_complete(inner)
  File "C:\Users\rullu\AppData\Local\Programs\Python\Python310\lib\asyncio\base_events.py", line 649, in run_until_complete
    return future.result()
  File "C:\Users\rullu\AppData\Local\Programs\Python\Python310\lib\site-packages\nbclient\client.py", line 709, in async_execute
    await self.async_execute_cell(
  File "C:\Users\rullu\AppData\Local\Programs\Python\Python310\lib\site-packages\nbclient\client.py", line 1062, in async_execute_cell
    await self._check_raise_for_error(cell, cell_index, exec_reply)
  File "C:\Users\rullu\AppData\Local\Programs\Python\Python310\lib\site-packages\nbclient\client.py", line 918, in _check_raise_for_error
    raise CellExecutionError.from_cell_and_msg(cell, exec_reply_content)
nbclient.exceptions.CellExecutionError: An error occurred while executing the following cell:
------------------
from DataStructureCode.LinkedQueue import *
queue = LinkedQueue()
queue.enqueue("Mon"); queue.enqueue("Tue"); queue.enqueue("Wed"); queue.enqueue("Thurs"); queue.enqueue("Fri")
queue.printQueue()

def reverseQueue(queue):


reverseQueue(queue)
print("After Reversing the queue:")
queue.printQueue()
------------------


[1;36m  Cell [1;32mIn[5], line 9[1;36m[0m
[1;33m    reverseQueue(queue)[0m
[1;37m    ^[0m
[1;31mIndentationError[0m[1;31m:[0m expected an indented block after function definition on line 6


